Workbook

Sheet 01.07.2026
A1: KERALA STATE ELECTRICITY BOARD LIMITED
A2: DAILY REPORT - WATER LEVELS OF MAJOR RESERVOIRS (As on 01.07.2026) 7.00 AM.
A3: Sl. No. | B3: Name of Reservoir | C3: District | D3: FRL (metre) | E3: Rule level (metre) | F3: Water level on date (metre) | G3: MWL (metre) | H3: Spillway Crest Level (metre) | I3: Blue Alert level (metre) | J3: Orange Alert level (metre) | K3: Red Alert Level (metre) | L3: Live Storage at FRL (MCM) | M3: Live Storage (MCM) | N3: % Storage | O3: % Storage wrt Live Storage at FRL | P3: Inflow (MCM) | Q3: Average Inflow (Cumecs) | R3: Power House Discharge (MCM) | S3: Spill (MCM) | T3: Current Spillway release (Cumecs) | U3: Total Outflow (MCM) | V3: Rain fall (mm) | W3: Remarks | X3: Generation (MU) | AA3: =0.224/8 -> 0.028
A4: 1 | B4: 2 | C4: 3 | D4: 4 | E4: 5 | F4: 6 | I4: 7 | J4: 8 | K4: 9 | M4: 10 | N4: 11 | O4: 15 | P4: 12 | Q4: 13 | R4: 14 | S4: 15 | T4: 16 | U4: 17=14+15 | V4: 18 | W4: 19
A5: 1 | B5: IDUKKI | C5: IDK | D5: 2403 | E5: 2375.33 | F5: 2321 | G5: 2408.5 ft | H5: 2373 ft | I5: =E5-8 -> 2367.33 | J5: =E5-2 -> 2373.33 | K5: =E5-1 -> 2374.33 | L5: 1459.49 | M5: 343.54 | N5: =ROUND((M5/L5)*100,2) -> 23.54 | O5: =(#REF!/L5) -> #REF! | P5: 3.911 | Q5: =ROUND((P5*1000000/(24*3600)),2) -> 45.27 | R5: 0.9804 | S5: 0 | T5: 0 | U5: =R5+S5 -> 0.9804 | V5: 23 | X5: 1.42
A6: 2 | B6: IDAMALAYAR | C6: EKM | D6: 169 | E6: 161.5 | F6: 138.52 | G6: 171 | H6: 161 | I6: =E6-1.5 -> 160 | J6: =E6-1 -> 160.5 | K6: =E6-0.5 -> 161 | L6: 1017.8 | M6: 281.12 | N6: =ROUND((M6/L6)*100,2) -> 27.62 | O6: =(#REF!/L6) -> #REF! | P6: 3.9416 | Q6: =ROUND((P6*1000000/(24*3600)),2) -> 45.62 | R6: 0 | S6: 0 | T6: 0 | U6: =R6+S6 -> 0 | V6: 17.2 | X6: 0
A7: 3 | B7: KAKKI - ANATHODE | C7: PTTA | D7: 981.46 | E7: 975.36 | F7: 947.81 | G7: 982.16 | H7: 975.36 | I7: =E7-2 -> 973.36 | J7: =E7-1 -> 974.36 | K7: =E7-0.5 -> 974.86 | L7: 446.51 | M7: 99.06 | N7: =ROUND((M7/L7)*100,2) -> 22.19 | O7: =(#REF!/L7) -> #REF! | P7: 1.5678 | Q7: =ROUND((P7*1000000/(24*3600)),2) -> 18.15 | R7: 0.4278 | S7: 0 | T7: 0 | U7: =R7+S7 -> 0.4278 | V7: 46 | X7: 0.69
A8: 4 | B8: BANASURASAGAR (K A S) | C8: WND | D8: 775.6 | E8: 771 | F8: 756.15 | G8: 775.6 | H8: 767 | I8: =E8-1.5 -> 769.5 | J8: =E8-1 -> 770 | K8: =E8-0.5 -> 770.5 | L8: 201 | M8: 21.55 | N8: =ROUND((M8/L8)*100,2) -> 10.72 | O8: =(#REF!/L8) -> #REF! | P8: 0.9 | Q8: =ROUND((P8*1000000/(24*3600)),2) -> 10.42 | S8: 0 | T8: 0 | U8: =R8+S8 -> 0 | V8: 16.4 | W8: Tunnel fully closed on 29.06.2026 at 11.15 am. Tunnel discharge- Nil | Z8: =0.16/8 -> 0.02
A9: 5 | B9: SHOLAYAR | C9: TSR | D9: 2663 | F9: 2589.5 | G9: 2663 ft | H9: 2642 ft | I9: 2658 | J9: 2660 | K9: 2661 | L9: 149.089 | M9: 19.09 | N9: =ROUND((M9/L9)*100,2) -> 12.8 | O9: =(#REF!/L9) -> #REF! | P9: 0.5987 | Q9: =ROUND((P9*1000000/(24*3600)),2) -> 6.93 | R9: 0.3269 | S9: 0 | T9: 0 | U9: =R9+S9 -> 0.3269 | V9: 29 | X9: 0.2063
A10: 6 | B10: MADUPETTY | C10: IDK | D10: 1599.59 | F10: 1568.1 | G10: 1599.59 | H10: 1594.71 | I10: 1596 | J10: 1597 | K10: 1598 | L10: 54.77 | M10: 2.39 | N10: =ROUND((M10/L10)*100,2) -> 4.36 | O10: =(#REF!/L10) -> #REF! | P10: 0.139 | Q10: =ROUND((P10*1000000/(24*3600)),2) -> 1.61 | R10: 0 | S10: 0 | T10: =Y10 -> 0 | U10: =R10+S10 -> 0 | V10: 10 | W10: Sluice discharge =0.489MCM | X10: 0 | Y10: =(S10*1000000)/(24*60*60) -> 0
A11: 7 | B11: ANAYIRANKAL | C11: IDK | D11: 1207.02 | F11: 1194.95 | G11: 1210.07 | H11: 1207.02 | I11: 1205.02 | J11: 1206.02 | K11: 1207.02 | L11: 49.83 | M11: 9.9482 | N11: =ROUND((M11/L11)*100,2) -> 19.96 | O11: =(#REF!/L11) -> #REF! | P11: 0.0694 | Q11: =ROUND((P11*1000000/(24*3600)),2) -> 0.8 | S11: 0 | T11: 0 | U11: =R11+S11 -> 0 | V11: 7 | W11: (Sluice gate fully closed @ 4.00 pm on 05.06.2026) | X11: 0 | Y11: =ROUND((S11*1000000/(24*3600)),2) -> 0
A12: 8 | B12: PONMUDI | C12: IDK | D12: 707.75 | F12: 691.15 | G12: 708.66 | H12: 701.35 | I12: 704.5 | J12: 705.5 | K12: 706.5 | L12: 47.4 | M12: 15.7885 | N12: =ROUND((M12/L12)*100,2) -> 33.31 | O12: =(#REF!/L12) -> #REF! | P12: 0.5527 | Q12: =ROUND((P12*1000000/(24*3600)),2) -> 6.4 | R12: 0 | S12: 0 | T12: 0 | U12: =R12+S12 -> 0 | V12: 27 | X12: 0 | Y12: =ROUND((S12*1000000/(24*3600)),2) -> 0
A13: 9 | B13: KUTTIYADI (KAKKAYAM) | C13: KKD | D13: 758.04 | F13: 747.61 | G13: 758.04 | H13: 751.64 | I13: 755.5 | J13: 756.5 | K13: 757.5 | L13: 33.98 | M13: 11.462 | N13: =ROUND((M13/L13)*100,2) -> 33.73 | O13: =(#REF!/L13) -> #REF! | P13: 1.4101 | Q13: =ROUND((P13*1000000/(24*3600)),2) -> 16.32 | R13: 0.0501 | S13: 0 | T13: 0 | U13: =R13+S13 -> 0.0501 | V13: 61 | X13: 0.0716
A14: 10 | B14: PAMBA | C14: PTTA | D14: 986.33 | F14: 964.45 | G14: 986.33 | H14: 981.46 | I14: 982 | J14: 983.5 | K14: 984.5 | L14: 31.15 | M14: 0.97 | N14: =ROUND((M14/L14)*100,2) -> 3.11 | O14: =(#REF!/L14) -> #REF! | P14: 1.357 | Q14: =ROUND((P14*1000000/(24*3600)),2) -> 15.71 | S14: 0 | T14: 0 | U14: =R14+S14 -> 0 | V14: 27 | X14: 0
A15: 11 | B15: PORINGALKUTHU | C15: TSR | D15: 423.98 | F15: 416 | G15: 423.98 | H15: 419.41 | I15: 421 | J15: 422 | K15: 423 | L15: 30.3 | M15: 11.1 | N15: =ROUND((M15/L15)*100,2) -> 36.63 | O15: =(#REF!/L15) -> #REF! | P15: 1.4767 | Q15: =ROUND((P15*1000000/(24*3600)),2) -> 17.09 | R15: 0.8992 | S15: 0 | T15: 0 | U15: =R15+S15 -> 0.8992 | V15: 33.4 | X15: 0.35358 | AB15: =0.0294/8 -> 0.003675
A16: 12 | B16: KUNDALA | C16: IDK | D16: 1758.69 | F16: 1746.35 | G16: 1759.3 | I16: 1755 | J16: 1756 | K16: 1757 | L16: 7.65 | M16: 1.358 | N16: =ROUND((M16/L16)*100,2) -> 17.75 | O16: =(#REF!/L16) -> #REF! | P16: 0.028 | Q16: =ROUND((P16*1000000/(24*3600)),2) -> 0.32 | R16: 0 | S16: 0 | T16: 0 | U16: =R16+S16 -> 0 | V16: 5 | W16: Sluice discharge = 0.00 MCM. All gates are closed | X16: 0 | Y16: =ROUND((S16*1000000/(24*3600)),2) -> 0
A17: 13 | B17: KALLARKUTTY | C17: IDK | D17: 456.59 | F17: 452.3 | G17: 456.9 | H17: 450.2 | K17: 455 | L17: 6.43 | M17: 3.862 | N17: =ROUND((M17/L17)*100,2) -> 60.06 | O17: =(#REF!/L17) -> #REF! | P17: 1.4011 | Q17: =ROUND((P17*1000000/(24*3600)),2) -> 16.22 | R17: 1.6817 | S17: 0 | T17: 0 | U17: =R17+S17 -> 1.6817 | V17: 22 | X17: 0.7876 | Y17: =(S17*1000000)/(24*60*60) -> 0 | Z17: =ROUND((0.054*1000000/(24*3600)),2) -> 0.63
A18: 14 | B18: ERATTAYAR | C18: IDK | D18: 754.38 | F18: 746.4 | G18: 754.38 | H18: 748.28 | K18: 748.28 | L18: 5.292 | M18: 0.5467 | N18: =ROUND((M18/L18)*100,2) -> 10.33 | Q18: =ROUND((P18*1000000/(24*3600)),2) -> 0 | S18: 0 | T18: 0 | U18: =R18+S18 -> 0 | V18: 0 | X18: 0
A19: 15 | B19: LOWER PERIYAR | C19: IDK | D19: 253 | F19: 248.4 | G19: 256 | H19: 237.74 | K19: 252 | L19: 4.55 | M19: 2.666 | N19: =ROUND((M19/L19)*100,2) -> 58.59 | O19: =(#REF!/L19) -> #REF! | P19: 2.1616 | Q19: =ROUND((P19*1000000/(24*3600)),2) -> 25.02 | R19: 2.3566 | S19: 0 | T19: 0 | U19: =R19+S19 -> 2.3566 | V19: 34 | X19: 1.085 | Y19: =ROUND((S19*1000000/(24*3600)),2) -> 0 | AA19: =ROUND((0.1728*1000000/(3*3600)),2) -> 16
A20: 16 | B20: MOOZHIYAR | C20: PTTA | D20: 192.63 | F20: 185.1 | G20: 192.94 | H20: 186.53 | K20: 190 | L20: 1.16 | M20: 0.283 | N20: =ROUND((M20/L20)*100,2) -> 24.4 | O20: =(#REF!/L20) -> #REF! | P20: 1.0692 | Q20: =ROUND((P20*1000000/(24*3600)),2) -> 12.38 | R20: 0.8716 | S20: 0 | T20: 0 | U20: =R20+S20 -> 0.8716 | V20: 18 | X20: 0.26817 | Y20: =ROUND((S20*1000000/(24*3600)),2) -> 0 | Z20: =ROUND((S20*1000000/(24*3600)),2) -> 0
A21: 17 | B21: KALLAR | C21: IDK | D21: 824.48 | F21: 820.2 | G21: 824.48 | H21: 818.38 | K21: 823.5 | L21: 0.763 | M21: 0.1913 | N21: =ROUND((M21/L21)*100,2) -> 25.07 | Q21: =ROUND((P21*1000000/(24*3600)),2) -> 0 | S21: 0 | T21: 0 | U21: =R21+S21 -> 0 | V21: 0 | X21: 0
A22: 18 | B22: SENGULAM | C22: IDK | D22: 847.64 | F22: 846.7 | G22: 849.49 | H22: 847.64 | L22: 0.39 | M22: 0.165 | N22: =ROUND((M22/L22)*100,2) -> 42.31 | O22: =(#REF!/L22) -> #REF! | P22: 0.7051 | Q22: =ROUND((P22*1000000/(24*3600)),2) -> 8.16 | R22: 0.7523 | S22: 0 | T22: 0 | U22: =R22+S22 -> 0.7523 | V22: 7.5 | X22: 0.5924
B23: Grand Total | L23: =SUM(L5:L22) -> 3547.554 | M23: =ROUND(SUM(M5:M22),2) -> 825.09 | N23: =ROUND((M23/L23)*100,2) -> 23.26 | O23: =(#REF!/L23) -> #REF!
B25: Spilling Dams : Nil | T25: Deputy Chief Engineer

Sheet MU
C1: DAM SAFETY ORGANISATION, KSEBL RESERVOIR STATISTICS - WATER YEAR 2026-2027 (1.06.2026 to 31.05.2027) | P1: 01.07.2026 7AM
A2: # | B2: RESERVOIR | C2: WATER LEVEL (M) | E2: LIVE STORAGE | J2: INFLOW (MU) | L2: GENERATION (MU) | N2: SPILL (MU) | P2: RAINFALL (MM) | S2: Cum. Inflow up to Yesterday | T2: Cum. Gen. up to Yesterday | U2: Cum. Spill. up to Yesterday | V2: Cum. rain up to Yesterday
C3: FRL | D3: TODAY | E3: FRL (MU) | F3: TODAY | H3: LAST DAY | J3: TODAY | K3: CUMULATIVE | L3: TODAY | M3: CUMULATIVE | N3: TODAY | O3: CUMULATIVE | P3: TODAY | Q3: CUMULATIVE
F4: MU | G4: % | H4: MU | I4: %
A5: 1 | B5: =[1]MCM_DATA!A5 -> IDUKKI ( WL in Feet) | C5: =[1]MCM_DATA!B5 -> 2403 | D5: ='01.07.2026'!F5 -> 2321 | E5: ='01.07.2026'!L5*1.5 -> 2189.235 | F5: ='01.07.2026'!M5*1.5 -> 515.31 | G5: =ROUND((F5/E5),4) -> 0.2354 | H5: 511.146 | I5: =ROUND((H5/E5),4) -> 0.2335 | J5: =ROUND(((('01.07.2026'!Q5*24*3600)/1000000)*1.5),2) -> 5.87 | K5: =J5+S5 -> 185.12 | L5: ='01.07.2026'!X5 -> 1.42 | M5: =L5+T5 -> 124.588 | N5: =ROUND(((('01.07.2026'!T5*24*3600)/1000000)*1.5),2) -> 0 | O5: =U5+N5 -> 0 | P5: ='01.07.2026'!V5 -> 23 | Q5: =P5+V5 -> 452.6 | S5: 179.25 | T5: 123.168 | U5: 0 | V5: 429.6
A6: 2 | B6: =[1]MCM_DATA!A6 -> IDAMALAYAR | C6: =[1]MCM_DATA!B6 -> 169 | D6: ='01.07.2026'!F6 -> 138.52 | E6: ='01.07.2026'!L6*0.25 -> 254.45 | F6: ='01.07.2026'!M6*0.25 -> 70.28 | G6: =ROUND((F6/E6),4) -> 0.2762 | H6: 69.30875 | I6: =ROUND((H6/E6),4) -> 0.2724 | J6: =ROUND(((('01.07.2026'!Q6*24*3600)/1000000)*0.25),2) -> 0.99 | K6: =J6+S6 -> 18.95 | L6: ='01.07.2026'!X6 -> 0 | M6: =L6+T6 -> 4.0681 | N6: =ROUND(((('01.07.2026'!T6*24*3600)/1000000)*0.25),2) -> 0 | O6: =U6+N6 -> 0 | P6: ='01.07.2026'!V6 -> 17.2 | Q6: =P6+V6 -> 652.2 | S6: 17.96 | T6: 4.0681 | U6: 0 | V6: 635
A7: 3 | B7: =[1]MCM_DATA!A7 -> KAKKI | C7: =[1]MCM_DATA!B7 -> 981.46 | D7: ='01.07.2026'!F7 -> 947.81 | E7: ='01.07.2026'!L7*1.918 -> 856.40618 | F7: ='01.07.2026'!M7*1.918 -> 189.99708 | G7: =ROUND((F7/E7),4) -> 0.2219 | H7: 187.81056 | I7: =ROUND((H7/E7),4) -> 0.2193 | J7: =ROUND(((('01.07.2026'!Q7*24*3600)/1000000)*1.918),2) -> 3.01 | K7: =J7+S7 -> 132.84 | L7: ='01.07.2026'!X7 -> 0.69 | M7: =L7+T7 -> 44.7218 | N7: =ROUND(((('01.07.2026'!T7*24*3600)/1000000)*1.918),2) -> 0 | O7: =U7+N7 -> 0 | P7: ='01.07.2026'!V7 -> 46 | Q7: =P7+V7 -> 846 | S7: 129.83 | T7: 44.0318 | U7: 0 | V7: 800
A8: 4 | B8: =[1]MCM_DATA!A8 -> PAMBA | C8: =[1]MCM_DATA!B8 -> 986.33 | D8: ='01.07.2026'!F14 -> 964.45 | E8: ='01.07.2026'!L14*1.918 -> 59.7457 | F8: ='01.07.2026'!M14*1.918 -> 1.86046 | G8: =ROUND((F8/E8),4) -> 0.0311 | H8: 1.6303 | I8: =ROUND((H8/E8),4) -> 0.0273 | J8: =ROUND(((('01.07.2026'!Q14*24*3600)/1000000)*1.918),2) -> 2.6 | K8: =J8+S8 -> 124.69 | N8: =ROUND(((('01.07.2026'!T14*24*3600)/1000000)*1.918),2) -> 0 | O8: =U8+N8 -> 0 | P8: ='01.07.2026'!V14 -> 27 | Q8: =P8+V8 -> 647 | S8: 122.09 | U8: 0 | V8: 620
A9: 5 | B9: =[1]MCM_DATA!A9 -> BANASURASAGAR | C9: =[1]MCM_DATA!B9 -> 775.6 | D9: ='01.07.2026'!F8 -> 756.15 | E9: ='01.07.2026'!L8*1.26 -> 253.26 | F9: ='01.07.2026'!M8*1.26 -> 27.153 | G9: =ROUND((F9/E9),4) -> 0.1072 | H9: 26.019 | I9: =ROUND((H9/E9),4) -> 0.1027 | J9: =ROUND(((('01.07.2026'!Q8*24*3600)/1000000)*1.26),2) -> 1.13 | K9: =J9+S9 -> 14.45 | L9: ='01.07.2026'!X13 -> 0.0716 | M9: =L9+T9 -> 23.2827 | N9: =ROUND(((('01.07.2026'!T8*24*3600)/1000000)*1.26),2) -> 0 | O9: =U9+N9 -> 0 | P9: ='01.07.2026'!V8 -> 16.4 | Q9: =P9+V9 -> 316.2 | S9: 13.32 | T9: 23.2111 | U9: 0 | V9: 299.8
A10: 6 | B10: =[1]MCM_DATA!A10 -> KAKKAYAM | C10: =[1]MCM_DATA!B10 -> 758.04 | D10: ='01.07.2026'!F13 -> 747.61 | E10: ='01.07.2026'!L13*1.26 -> 42.8148 | F10: ='01.07.2026'!M13*1.26 -> 14.44212 | G10: =ROUND((F10/E10),4) -> 0.3373 | H10: 12.72852 | I10: =ROUND((H10/E10),4) -> 0.2973 | J10: =ROUND(((('01.07.2026'!Q13*24*3600)/1000000)*1.26),2) -> 1.78 | K10: =J10+S10 -> 23.35 | N10: =ROUND(((('01.07.2026'!T13*24*3600)/1000000)*1.26),2) -> 0 | O10: =U10+N10 -> 0 | P10: ='01.07.2026'!V13 -> 61 | Q10: =P10+V10 -> 936 | S10: 21.57 | U10: 0 | V10: 875
A11: 7 | B11: =[1]MCM_DATA!A11 -> SHOLAYAR (WL in Feet) | C11: =[1]MCM_DATA!B11 -> 2663 | D11: ='01.07.2026'!F9 -> 2589.5 | E11: ='01.07.2026'!L9*1.02 -> 152.07078 | F11: ='01.07.2026'!M9*1.02 -> 19.4718 | G11: =ROUND((F11/E11),4) -> 0.128 | H11: 19.1862 | I11: =ROUND((H11/E11),4) -> 0.1262 | J11: =ROUND(((('01.07.2026'!Q9*24*3600)/1000000)*1.02),2) -> 0.61 | K11: =J11+S11 -> 12.73 | L11: ='01.07.2026'!X9 -> 0.2063 | M11: =L11+T11 -> 7.6169 | N11: =ROUND(((('01.07.2026'!T9*24*3600)/1000000)*1.02),2) -> 0 | O11: =U11+N11 -> 0 | P11: ='01.07.2026'!V9 -> 29 | Q11: =P11+V11 -> 521.6 | S11: 12.12 | T11: 7.4106 | U11: 0 | V11: 492.6
A12: 8 | B12: =[1]MCM_DATA!A12 -> KUNDALA | C12: =[1]MCM_DATA!B12 -> 1758.69 | D12: ='01.07.2026'!F16 -> 1746.35 | E12: ='01.07.2026'!L16*2.92 -> 22.338 | F12: ='01.07.2026'!M16*2.92 -> 3.96536 | G12: =ROUND((F12/E12),4) -> 0.1775 | H12: 3.8836 | I12: =ROUND((H12/E12),4) -> 0.1739 | J12: =ROUND(((('01.07.2026'!Q16*24*3600)/1000000)*2.92),2) -> 0.08 | K12: =J12+S12 -> 9.39 | L12: ='01.07.2026'!X10 -> 0 | M12: =T12+L12 -> 0 | N12: =ROUND(((('01.07.2026'!T16*24*3600)/1000000)*2.92),2) -> 0 | O12: =U12+N12 -> 0 | P12: ='01.07.2026'!V16 -> 5 | Q12: =P12+V12 -> 183.4 | S12: 9.31 | T12: 0 | U12: 0 | V12: 178.4
A13: 9 | B13: =[1]MCM_DATA!A13 -> MADUPETTY | C13: =[1]MCM_DATA!B13 -> 1599.59 | D13: ='01.07.2026'!F10 -> 1568.1 | E13: ='01.07.2026'!L10*1.263 -> 69.17451 | F13: ='01.07.2026'!M10*1.263 -> 3.01857 | G13: =ROUND((F13/E13),4) -> 0.0436 | H13: 3.46062 | I13: =ROUND((H13/E13),4) -> 0.05 | J13: =ROUND(((('01.07.2026'!Q10*24*3600)/1000000)*1.263),2) -> 0.18 | K13: =J13+S13 -> 10.6 | N13: =ROUND(((('01.07.2026'!T10*24*3600)/1000000)*1.263),2) -> 0 | O13: =U13+N13 -> 0 | P13: ='01.07.2026'!V10 -> 10 | Q13: =P13+V13 -> 270.4 | S13: 10.42 | U13: 0 | V13: 260.4
A14: 10 | B14: =[1]MCM_DATA!A14 -> ANAYIRANKAL | C14: =[1]MCM_DATA!B14 -> 1207.02 | D14: ='01.07.2026'!F11 -> 1194.95 | E14: ='01.07.2026'!L11*1.34 -> 66.7722 | F14: ='01.07.2026'!M11*1.34 -> 13.330588 | G14: =ROUND((F14/E14),4) -> 0.1996 | H14: 13.237592 | I14: =ROUND((H14/E14),4) -> 0.1983 | J14: =ROUND(((('01.07.2026'!Q11*24*3600)/1000000)*1.34),2) -> 0.09 | K14: =J14+S14 -> 11.77 | L14: ='01.07.2026'!X12 -> 0 | M14: =T14+L14 -> 6.1216 | N14: =ROUND(((('01.07.2026'!T11*24*3600)/1000000)*1.34),2) -> 0 | O14: =U14+N14 -> 0 | P14: ='01.07.2026'!V11 -> 7 | Q14: =P14+V14 -> 245 | S14: 11.68 | T14: 6.1216 | U14: 0 | V14: 238
A15: 11 | B15: =[1]MCM_DATA!A15 -> PONMUDUI | C15: =[1]MCM_DATA!B15 -> 707.75 | D15: ='01.07.2026'!F12 -> 691.15 | E15: ='01.07.2026'!L12*1.34 -> 63.516 | F15: ='01.07.2026'!M12*1.34 -> 21.15659 | G15: =ROUND((F15/E15),4) -> 0.3331 | H15: 20.415972 | I15: =ROUND((H15/E15),4) -> 0.3214 | J15: =ROUND(((('01.07.2026'!Q12*24*3600)/1000000)*1.34),2) -> 0.74 | K15: =J15+S15 -> 26.62 | N15: =ROUND(((('01.07.2026'!T12*24*3600)/1000000)*1.34),2) -> 0 | O15: =U15+N15 -> 0 | P15: ='01.07.2026'!V12 -> 27 | Q15: =P15+V15 -> 355 | S15: 25.88 | U15: 0 | V15: 328
A16: 12 | B16: =[1]MCM_DATA!A16 -> PORINGALKUTHU | C16: =[1]MCM_DATA!B16 -> 423.98 | D16: ='01.07.2026'!F15 -> 416 | E16: ='01.07.2026'!L15*0.35 -> 10.605 | F16: ='01.07.2026'!M15*0.35 -> 3.885 | G16: =ROUND((F16/E16),4) -> 0.3663 | H16: 3.682 | I16: =ROUND((H16/E16),4) -> 0.3472 | J16: =ROUND(((('01.07.2026'!Q15*24*3600)/1000000)*0.35),2) -> 0.52 | K16: =J16+S16 -> 13.5 | L16: ='01.07.2026'!X15 -> 0.35358 | M16: =L16+T16 -> 14.0073 | N16: =ROUND(((('01.07.2026'!T15*24*3600)/1000000)*0.35),2) -> 0 | O16: =U16+N16 -> 0 | P16: ='01.07.2026'!V15 -> 33.4 | Q16: =P16+V16 -> 679.8 | S16: 12.98 | T16: 13.65372 | U16: 0 | V16: 646.4
A17: 13 | B17: =[1]MCM_DATA!A17 -> KALLARKUTTY | C17: =[1]MCM_DATA!B17 -> 456.95 | D17: ='01.07.2026'!F17 -> 452.3 | E17: ='01.07.2026'!L17*0.87 -> 5.5941 | F17: ='01.07.2026'!M17*0.87 -> 3.35994 | G17: =ROUND((F17/E17),4) -> 0.6006 | H17: 3.60354 | I17: =ROUND((H17/E17),4) -> 0.6442 | J17: =ROUND(((('01.07.2026'!Q17*24*3600)/1000000)*0.87),2) -> 1.22 | K17: =J17+S17 -> 44.59 | L17: ='01.07.2026'!X17 -> 0.7876 | M17: =L17+T17 -> 24.3138 | N17: =ROUND(((('01.07.2026'!T17*24*3600)/1000000)*0.87),2) -> 0 | O17: =U17+N17 -> 0 | P17: ='01.07.2026'!V17 -> 22 | Q17: =P17+V17 -> 374 | S17: 43.37 | T17: 23.5262 | U17: 0 | V17: 352
A18: 14 | B18: =[1]MCM_DATA!A18 -> LOWER PERIYAR | C18: =[1]MCM_DATA!B18 -> 253 | D18: ='01.07.2026'!F19 -> 248.4 | E18: ='01.07.2026'!L19*0.46 -> 2.093 | F18: ='01.07.2026'!M19*0.46 -> 1.22636 | G18: =ROUND((F18/E18),4) -> 0.5859 | H18: 1.31606 | I18: =ROUND((H18/E18),4) -> 0.6288 | J18: =ROUND(((('01.07.2026'!Q19*24*3600)/1000000)*0.46),2) -> 0.99 | K18: =J18+S18 -> 29.84 | L18: ='01.07.2026'!X19 -> 1.085 | M18: =L18+T18 -> 29.956 | N18: =ROUND(((('01.07.2026'!T19*24*3600)/1000000)*0.46),2) -> 0 | O18: =U18+N18 -> 0 | P18: ='01.07.2026'!V19 -> 34 | Q18: =P18+V18 -> 472 | S18: 28.85 | T18: 28.871 | U18: 0 | V18: 438
A19: 15 | B19: =[1]MCM_DATA!A19 -> MOOZHIYAR | C19: =[1]MCM_DATA!B19 -> 192.63 | D19: ='01.07.2026'!F20 -> 185.1 | E19: ='01.07.2026'!L20*0.308 -> 0.35728 | F19: ='01.07.2026'!M20*0.308 -> 0.087164 | G19: =ROUND((F19/E19),4) -> 0.244 | H19: 0.1155 | I19: =ROUND((H19/E19),4) -> 0.3233 | J19: =ROUND(((('01.07.2026'!Q20*24*3600)/1000000)*0.308),2) -> 0.33 | K19: =J19+S19 -> 10.91 | L19: ='01.07.2026'!X20 -> 0.26817 | M19: =L19+T19 -> 12.03444 | N19: =ROUND(((('01.07.2026'!T20*24*3600)/1000000)*0.308),4) -> 0 | O19: =U19+N19 -> 0 | P19: ='01.07.2026'!V20 -> 18 | Q19: =P19+V19 -> 633 | S19: 10.58 | T19: 11.76627 | U19: 0 | V19: 615
A20: 16 | B20: =[1]MCM_DATA!A20 -> SENGULAM | C20: =[1]MCM_DATA!B20 -> 847.64 | D20: ='01.07.2026'!F22 -> 846.7 | E20: ='01.07.2026'!L22*0.79 -> 0.3081 | F20: ='01.07.2026'!M22*0.79 -> 0.13035 | G20: =ROUND((F20/E20),4) -> 0.4231 | H20: 0.16827 | I20: =ROUND((H20/E20),4) -> 0.5462 | J20: =ROUND(((('01.07.2026'!Q22*24*3600)/1000000)*0.79),2) -> 0.56 | K20: =J20+S20 -> 16.75 | L20: ='01.07.2026'!X22 -> 0.5924 | M20: =L20+T20 -> 16.7294 | N20: =ROUND(((('01.07.2026'!T22*24*3600)/1000000)*0.79),2) -> 0 | O20: =U20+N20 -> 0 | P20: ='01.07.2026'!V22 -> 7.5 | Q20: =P20+V20 -> 132.2 | S20: 16.19 | T20: 16.137 | U20: 0 | V20: 124.7
A21: GRAND TOTAL | F21: =SUM(F5:F20) -> 888.67438 | H21: =SUM(H5:H20) -> 877.71248 | J21: =SUM(J5:J20) -> 20.7 | K21: =SUM(K5:K20) -> 686.1 | L21: =SUM(L5:L20) -> 5.47465 | M21: =SUM(M5:M20) -> 307.44004 | N21: =SUM(N5:N20) -> 0 | O21: =SUM(O5:O20) -> 0
N23: Sd/-
N24: Deputy Chief Engineer
N25: Research & Dam Safety Organization
N26: Pallom, Kottayam
A27: 1 | B27: Before editing copy Coulmn "F" and paste as values to column "H"
A28: 2 | B28: For cumulative inflow copy copy column "K" to Column "S" as values
A29: 3 | B29: For cumulative generation copy copy column "M" to Column "T" as values
A30: 4 | B30: For cumulative spill, copy copy column "O" to Column "U" as values
A31: 5 | B31: For cumulative rainfall, copy copy column "Q" to Column "V" as values
A32: 6 | B32: Enter todays generation to column "X" at 18 Dams sheet from dam safety group ( Madupetty Kundala from SLDC Site)

Sheet FB
A1: കേരള സ്റ്റേറ്റ് ഇലക്ട്രിസിറ്റി ബോർഡ് ലിമിറ്റഡ്
A2: (കേരളത്തിലെ പ്രധാന അണക്കെട്ടുകളിലെ (KSEBL) ദിനേനയുള്ള ജലനിരപ്പ് സംബന്ധിച്ചുള്ള വിവരം)
A3: ='01.07.2026'!A2:W2 -> DAILY REPORT - WATER LEVELS OF MAJOR RESERVOIRS (As on 01.07.2026) 7.00 AM.
A4: Sl. No. | B4: അണക്കെട്ട് Name of Dam | C4: പരമാവധി ജലനിരപ്പ് (മീറ്റർ) FRL in (m) | D4: പൂർണ്ണ സംഭരണശേഷി Total Live Storage at FRL (MCM) | E4: നിലവിലെ ജലനിരപ്പ് Water level as on date (m) | F4: നിലവിലെ മൊത്ത സംഭരണo Live Storage as on Date (MCM) | G4: നിലവിലെ മൊത്ത സംഭരണ ശതമാനം Live Storage Percentage | H4: പുറത്ത് വിടുന്ന വെള്ളം Spill (cumecs) | I4: കുറിപ്പ് Remarks
A5: 1 | B5: 2 | C5: 3 | D5: 4 | E5: 5 | F5: 6 | G5: 7 | H5: 8 | I5: 9
A6: 1 | B6: ഇടുക്കി - IDUKKI | C6: 2403 അടി (feet) | D6: 1459.49 | E6: ='01.07.2026'!F5 -> 2321 | F6: ='01.07.2026'!M5 -> 343.54 | G6: =ROUND((F6/D6),4) -> 0.2354 | H6: ='01.07.2026'!T5 -> 0
A7: 2 | B7: ഇടമലയാർ - IDAMALAYAR | C7: 169 | D7: 1017.8 | E7: ='01.07.2026'!F6 -> 138.52 | F7: ='01.07.2026'!M6 -> 281.12 | G7: =ROUND((F7/D7),4) -> 0.2762 | H7: ='01.07.2026'!T6 -> 0
A8: 3 | B8: കക്കി (ആനത്തോട്) - KAKKI (ANATHODE ) | C8: 981.46 | D8: 446.51 | E8: ='01.07.2026'!F7 -> 947.81 | F8: ='01.07.2026'!M7 -> 99.06 | G8: =ROUND((F8/D8),4) -> 0.2219 | H8: ='01.07.2026'!T7 -> 0
A9: 4 | B9: ബാണാസുരസാഗർ -BANASURASAGAR | C9: 775.6 | D9: 201 | E9: ='01.07.2026'!F8 -> 756.15 | F9: ='01.07.2026'!M8 -> 21.55 | G9: =ROUND((F9/D9),4) -> 0.1072 | H9: ='01.07.2026'!T8 -> 0
A10: 5 | B10: ഷോളയാർ - SHOLAYAR | C10: 2663 അടി (feet) | D10: 149.09 | E10: ='01.07.2026'!F9 -> 2589.5 | F10: ='01.07.2026'!M9 -> 19.09 | G10: =ROUND((F10/D10),4) -> 0.128 | H10: ='01.07.2026'!T9 -> 0
A11: 6 | B11: മാടുപെട്ടി -MADUPETTY | C11: 1599.59 | D11: 54.77 | E11: ='01.07.2026'!F10 -> 1568.1 | F11: ='01.07.2026'!M10 -> 2.39 | G11: =ROUND((F11/D11),4) -> 0.0436 | H11: ='01.07.2026'!T10 -> 0
A12: 7 | B12: ആനയിറങ്കൽ ANAYIRANKAL | C12: 1207.02 | D12: 49.83 | E12: ='01.07.2026'!F11 -> 1194.95 | F12: ='01.07.2026'!M11 -> 9.9482 | G12: =ROUND((F12/D12),4) -> 0.1996 | H12: ='01.07.2026'!T11 -> 0
A13: 8 | B13: പൊന്മുടി - PONMUDI | C13: 707.93 | D13: 47.4 | E13: ='01.07.2026'!F12 -> 691.15 | F13: ='01.07.2026'!M12 -> 15.7885 | G13: =ROUND((F13/D13),4) -> 0.3331 | H13: ='01.07.2026'!T12 -> 0
A14: 9 | B14: കുറ്റിയാടി - KUTTIYADI | C14: 758.04 | D14: 33.98 | E14: ='01.07.2026'!F13 -> 747.61 | F14: ='01.07.2026'!M13 -> 11.462 | G14: =ROUND((F14/D14),4) -> 0.3373 | H14: ='01.07.2026'!T13 -> 0
A15: 10 | B15: പമ്പ - PAMBA | C15: 986.33 | D15: 31.15 | E15: ='01.07.2026'!F14 -> 964.45 | F15: ='01.07.2026'!M14 -> 0.97 | G15: =ROUND((F15/D15),4) -> 0.0311 | H15: ='01.07.2026'!T14 -> 0
A16: 11 | B16: പൊരിങ്ങൽകുത്ത് - PORINGALKUTHU | C16: 423.98 | D16: 30.3 | E16: ='01.07.2026'!F15 -> 416 | F16: ='01.07.2026'!M15 -> 11.1 | G16: =ROUND((F16/D16),4) -> 0.3663 | H16: ='01.07.2026'!T15 -> 0
A17: 12 | B17: കുണ്ടള - KUNDALA | C17: 1758.696 | D17: 7.65 | E17: ='01.07.2026'!F16 -> 1746.35 | F17: ='01.07.2026'!M16 -> 1.358 | G17: =ROUND((F17/D17),4) -> 0.1775 | H17: ='01.07.2026'!T16 -> 0
A18: 13 | B18: കല്ലാർകുട്ടി - KALLARKUTTY | C18: 456.59 | D18: 6.43 | E18: ='01.07.2026'!F17 -> 452.3 | F18: ='01.07.2026'!M17 -> 3.862 | G18: =ROUND((F18/D18),4) -> 0.6006 | H18: ='01.07.2026'!T17 -> 0
A19: 14 | B19: ഇരട്ടയാർ - ERATTAYAR | C19: 754.38 | D19: 5.292 | E19: ='01.07.2026'!F18 -> 746.4 | F19: ='01.07.2026'!M18 -> 0.5467 | G19: =ROUND((F19/D19),4) -> 0.1033 | H19: ='01.07.2026'!T18 -> 0
A20: 15 | B20: ലോവർ പെരിയാർ - LOWER PERIYAR | C20: 253 | D20: 4.55 | E20: ='01.07.2026'!F19 -> 248.4 | F20: ='01.07.2026'!M19 -> 2.666 | G20: =ROUND((F20/D20),4) -> 0.5859 | H20: ='01.07.2026'!T19 -> 0
A21: 16 | B21: മൂഴിയാർ - MOOZHIYAR | C21: 192.63 | D21: 1.16 | E21: ='01.07.2026'!F20 -> 185.1 | F21: ='01.07.2026'!M20 -> 0.283 | G21: =ROUND((F21/D21),4) -> 0.244 | H21: ='01.07.2026'!T20 -> 0
A22: 17 | B22: കല്ലാർ - KALLAR | C22: 824.48 | D22: 0.763 | E22: ='01.07.2026'!F21 -> 820.2 | F22: ='01.07.2026'!M21 -> 0.1913 | G22: =ROUND((F22/D22),4) -> 0.2507 | H22: ='01.07.2026'!T21 -> 0
A23: 18 | B23: ചെങ്കുളം - SENGULAM | C23: 847.64 | D23: 0.39 | E23: ='01.07.2026'!F22 -> 846.7 | F23: ='01.07.2026'!M22 -> 0.165 | G23: =ROUND((F23/D23),4) -> 0.4231 | H23: ='01.07.2026'!T22 -> 0

Sheet 02.07.2026
A1: KERALA STATE ELECTRICITY BOARD LIMITED
A2: DAILY REPORT - WATER LEVELS OF MAJOR RESERVOIRS (As on 02.07.2026) 7.00 AM.
A3: Sl. No. | B3: Name of Reservoir | C3: District | D3: FRL (metre) | E3: Rule level (metre) | F3: Water level on date (metre) | G3: MWL (metre) | H3: Spillway Crest Level (metre) | I3: Blue Alert level (metre) | J3: Orange Alert level (metre) | K3: Red Alert Level (metre) | L3: Live Storage at FRL (MCM) | M3: Live Storage (MCM) | N3: % Storage | O3: % Storage wrt Live Storage at FRL | P3: Inflow (MCM) | Q3: Average Inflow (Cumecs) | R3: Power House Discharge (MCM) | S3: Spill (MCM) | T3: Current Spillway release (Cumecs) | U3: Total Outflow (MCM) | V3: Rain fall (mm) | W3: Remarks | X3: Generation (MU) | AA3: =0.224/8 -> 0.028
A4: 1 | B4: 2 | C4: 3 | D4: 4 | E4: 5 | F4: 6 | I4: 7 | J4: 8 | K4: 9 | M4: 10 | N4: 11 | O4: 15 | P4: 12 | Q4: 13 | R4: 14 | S4: 15 | T4: 16 | U4: 17=14+15 | V4: 18 | W4: 19
A5: 1 | B5: IDUKKI | C5: IDK | D5: 2403 | E5: 2375.33 | F5: 2321.24 | G5: 2408.5 ft | H5: 2373 ft | I5: =E5-8 -> 2367.33 | J5: =E5-2 -> 2373.33 | K5: =E5-1 -> 2374.33 | L5: 1459.49 | M5: 346.102 | N5: =ROUND((M5/L5)*100,2) -> 23.71 | O5: =(#REF!/L5) -> #REF! | P5: 4.145 | Q5: =ROUND((P5*1000000/(24*3600)),2) -> 47.97 | R5: 1.4283 | S5: 0 | T5: 0 | U5: =R5+S5 -> 1.4283 | V5: 6.4 | X5: 2.069
A6: 2 | B6: IDAMALAYAR | C6: EKM | D6: 169 | E6: 161.5 | F6: 138.77 | G6: 171 | H6: 161 | I6: =E6-1.5 -> 160 | J6: =E6-1 -> 160.5 | K6: =E6-0.5 -> 161 | L6: 1017.8 | M6: 285.745 | N6: =ROUND((M6/L6)*100,2) -> 28.07 | O6: =(#REF!/L6) -> #REF! | P6: 4.6455 | Q6: =ROUND((P6*1000000/(24*3600)),2) -> 53.77 | R6: 0.0067 | S6: 0 | T6: 0 | U6: =R6+S6 -> 0.0067 | V6: 15.8 | X6: 0.0016
A7: 3 | B7: KAKKI - ANATHODE | C7: PTTA | D7: 981.46 | E7: 975.36 | F7: 947.99 | G7: 982.16 | H7: 975.36 | I7: =E7-2 -> 973.36 | J7: =E7-1 -> 974.36 | K7: =E7-0.5 -> 974.86 | L7: 446.51 | M7: 100 | N7: =ROUND((M7/L7)*100,2) -> 22.4 | O7: =(#REF!/L7) -> #REF! | P7: 1.3002 | Q7: =ROUND((P7*1000000/(24*3600)),2) -> 15.05 | R7: 0.3602 | S7: 0 | T7: 0 | U7: =R7+S7 -> 0.3602 | V7: 4 | X7: 0.581
A8: 4 | B8: BANASURASAGAR (K A S) | C8: WND | D8: 775.6 | E8: 771 | F8: 756.4 | G8: 775.6 | H8: 767 | I8: =E8-1.5 -> 769.5 | J8: =E8-1 -> 770 | K8: =E8-0.5 -> 770.5 | L8: 201 | M8: 23.15 | N8: =ROUND((M8/L8)*100,2) -> 11.52 | O8: =(#REF!/L8) -> #REF! | P8: 1.6 | Q8: =ROUND((P8*1000000/(24*3600)),2) -> 18.52 | S8: 0 | T8: 0 | U8: =R8+S8 -> 0 | V8: 17 | W8: Tunnel fully closed on 29.06.2026 at 11.15 am. Tunnel discharge- Nil | Z8: =0.16/8 -> 0.02
A9: 5 | B9: SHOLAYAR | C9: TSR | D9: 2663 | F9: 2590.6 | G9: 2663 ft | H9: 2642 ft | I9: 2658 | J9: 2660 | K9: 2661 | L9: 149.089 | M9: 20.08 | N9: =ROUND((M9/L9)*100,2) -> 13.47 | O9: =(#REF!/L9) -> #REF! | P9: 0.9968 | Q9: =ROUND((P9*1000000/(24*3600)),2) -> 11.54 | R9: 0 | S9: 0 | T9: 0 | U9: =R9+S9 -> 0 | V9: 23 | X9: 0
A10: 6 | B10: MADUPETTY | C10: IDK | D10: 1599.59 | F10: 1267.8 | G10: 1599.59 | H10: 1594.71 | I10: 1596 | J10: 1597 | K10: 1598 | L10: 54.77 | M10: 2.09 | N10: =ROUND((M10/L10)*100,2) -> 3.82 | O10: =(#REF!/L10) -> #REF! | P10: 0.189 | Q10: =ROUND((P10*1000000/(24*3600)),2) -> 2.19 | R10: 0 | S10: 0 | T10: =Y10 -> 0 | U10: =R10+S10 -> 0 | V10: 8.6 | W10: Sluice discharge =0.489MCM | X10: 0 | Y10: =(S10*1000000)/(24*60*60) -> 0
A11: 7 | B11: ANAYIRANKAL | C11: IDK | D11: 1207.02 | F11: 1194.99 | G11: 1210.07 | H11: 1207.02 | I11: 1205.02 | J11: 1206.02 | K11: 1207.02 | L11: 49.83 | M11: 10.0176 | N11: =ROUND((M11/L11)*100,2) -> 20.1 | O11: =(#REF!/L11) -> #REF! | P11: 0.0694 | Q11: =ROUND((P11*1000000/(24*3600)),2) -> 0.8 | S11: 0 | T11: 0 | U11: =R11+S11 -> 0 | V11: 5 | W11: (Sluice gate fully closed @ 4.00 pm on 05.06.2026) | X11: 0 | Y11: =ROUND((S11*1000000/(24*3600)),2) -> 0
A12: 8 | B12: PONMUDI | C12: IDK | D12: 707.75 | F12: 691.35 | G12: 708.66 | H12: 701.35 | I12: 704.5 | J12: 705.5 | K12: 706.5 | L12: 47.4 | M12: 16.1043 | N12: =ROUND((M12/L12)*100,2) -> 33.98 | O12: =(#REF!/L12) -> #REF! | P12: 0.3158 | Q12: =ROUND((P12*1000000/(24*3600)),2) -> 3.66 | R12: 0 | S12: 0 | T12: 0 | U12: =R12+S12 -> 0 | V12: 12 | X12: 0 | Y12: =ROUND((S12*1000000/(24*3600)),2) -> 0
A13: 9 | B13: KUTTIYADI (KAKKAYAM) | C13: KKD | D13: 758.04 | F13: 748.34 | G13: 758.04 | H13: 751.64 | I13: 755.5 | J13: 756.5 | K13: 757.5 | L13: 33.98 | M13: 12.7148 | N13: =ROUND((M13/L13)*100,2) -> 37.42 | O13: =(#REF!/L13) -> #REF! | P13: 1.2528 | Q13: =ROUND((P13*1000000/(24*3600)),2) -> 14.5 | R13: 0 | S13: 0 | T13: 0 | U13: =R13+S13 -> 0 | V13: 43 | X13: 0
A14: 10 | B14: PAMBA | C14: PTTA | D14: 986.33 | F14: 964.45 | G14: 986.33 | H14: 981.46 | I14: 982 | J14: 983.5 | K14: 984.5 | L14: 31.15 | M14: 0.97 | N14: =ROUND((M14/L14)*100,2) -> 3.11 | O14: =(#REF!/L14) -> #REF! | P14: 1.339 | Q14: =ROUND((P14*1000000/(24*3600)),2) -> 15.5 | S14: 0 | T14: 0 | U14: =R14+S14 -> 0 | V14: 27 | X14: 0
A15: 11 | B15: PORINGALKUTHU | C15: TSR | D15: 423.98 | F15: 417.2 | G15: 423.98 | H15: 419.41 | I15: 421 | J15: 422 | K15: 423 | L15: 30.3 | M15: 13.5 | N15: =ROUND((M15/L15)*100,2) -> 44.55 | O15: =(#REF!/L15) -> #REF! | P15: 3.6054 | Q15: =ROUND((P15*1000000/(24*3600)),2) -> 41.73 | R15: 1.2054 | S15: 0 | T15: 0 | U15: =R15+S15 -> 1.2054 | V15: 24.2 | X15: 0.48294 | AB15: =0.0294/8 -> 0.003675
A16: 12 | B16: KUNDALA | C16: IDK | D16: 1758.69 | F16: 1746.45 | G16: 1759.3 | I16: 1755 | J16: 1756 | K16: 1757 | L16: 7.65 | M16: 1.386 | N16: =ROUND((M16/L16)*100,2) -> 18.12 | O16: =(#REF!/L16) -> #REF! | P16: 0.028 | Q16: =ROUND((P16*1000000/(24*3600)),2) -> 0.32 | R16: 0 | S16: 0 | T16: 0 | U16: =R16+S16 -> 0 | V16: 3 | W16: Sluice discharge = 0.00 MCM. All gates are closed | X16: 0 | Y16: =ROUND((S16*1000000/(24*3600)),2) -> 0
A17: 13 | B17: KALLARKUTTY | C17: IDK | D17: 456.59 | F17: 452.25 | G17: 456.9 | H17: 450.2 | K17: 455 | L17: 6.43 | M17: 3.836 | N17: =ROUND((M17/L17)*100,2) -> 59.66 | O17: =(#REF!/L17) -> #REF! | P17: 1.8195 | Q17: =ROUND((P17*1000000/(24*3600)),2) -> 21.06 | R17: 1.845 | S17: 0 | T17: 0 | U17: =R17+S17 -> 1.845 | V17: 16 | X17: 0.8644 | Y17: =(S17*1000000)/(24*60*60) -> 0 | Z17: =ROUND((0.054*1000000/(24*3600)),2) -> 0.63
A18: 14 | B18: ERATTAYAR | C18: IDK | D18: 754.38 | F18: 746.4 | G18: 754.38 | H18: 748.28 | K18: 748.28 | L18: 5.292 | M18: 0.5467 | N18: =ROUND((M18/L18)*100,2) -> 10.33 | Q18: =ROUND((P18*1000000/(24*3600)),2) -> 0 | S18: 0 | T18: 0 | U18: =R18+S18 -> 0 | V18: 0 | X18: 0
A19: 15 | B19: LOWER PERIYAR | C19: IDK | D19: 253 | F19: 248.3 | G19: 256 | H19: 237.74 | K19: 252 | L19: 4.55 | M19: 2.627 | N19: =ROUND((M19/L19)*100,2) -> 57.74 | O19: =(#REF!/L19) -> #REF! | P19: 3.0148 | Q19: =ROUND((P19*1000000/(24*3600)),2) -> 34.89 | R19: 3.0538 | S19: 0 | T19: 0 | U19: =R19+S19 -> 3.0538 | V19: 28 | X19: 1.406 | Y19: =ROUND((S19*1000000/(24*3600)),2) -> 0 | AA19: =ROUND((0.1728*1000000/(3*3600)),2) -> 16
A20: 16 | B20: MOOZHIYAR | C20: PTTA | D20: 192.63 | F20: 185.7 | G20: 192.94 | H20: 186.53 | K20: 190 | L20: 1.16 | M20: 0.336 | N20: =ROUND((M20/L20)*100,2) -> 28.97 | O20: =(#REF!/L20) -> #REF! | P20: 1.025 | Q20: =ROUND((P20*1000000/(24*3600)),2) -> 11.86 | R20: 0.8279 | S20: 0 | T20: 0 | U20: =R20+S20 -> 0.8279 | V20: 12 | X20: 0.25475 | Y20: =ROUND((S20*1000000/(24*3600)),2) -> 0 | Z20: =ROUND((S20*1000000/(24*3600)),2) -> 0
A21: 17 | B21: KALLAR | C21: IDK | D21: 824.48 | F21: 820.2 | G21: 824.48 | H21: 818.38 | K21: 823.5 | L21: 0.763 | M21: 0.1913 | N21: =ROUND((M21/L21)*100,2) -> 25.07 | Q21: =ROUND((P21*1000000/(24*3600)),2) -> 0 | S21: 0 | T21: 0 | U21: =R21+S21 -> 0 | V21: 0 | X21: 0
A22: 18 | B22: SENGULAM | C22: IDK | D22: 847.64 | F22: 846.6 | G22: 849.49 | H22: 847.64 | L22: 0.39 | M22: 0.142 | N22: =ROUND((M22/L22)*100,2) -> 36.41 | O22: =(#REF!/L22) -> #REF! | P22: 0.9493 | Q22: =ROUND((P22*1000000/(24*3600)),2) -> 10.99 | R22: 0.972947 | S22: 0 | T22: 0 | U22: =R22+S22 -> 0.972947 | V22: 5.5 | X22: 0.7661
B23: Grand Total | L23: =SUM(L5:L22) -> 3547.554 | M23: =ROUND(SUM(M5:M22),2) -> 839.54 | N23: =ROUND((M23/L23)*100,2) -> 23.67 | O23: =(#REF!/L23) -> #REF!
B25: Spilling Dams : Nil | T25: Deputy Chief Engineer

Sheet 03.07.2026
A1: KERALA STATE ELECTRICITY BOARD LIMITED
A2: DAILY REPORT - WATER LEVELS OF MAJOR RESERVOIRS (As on 03.07.2026) 7.00 AM.
A3: Sl. No. | B3: Name of Reservoir | C3: District | D3: FRL (metre) | E3: Rule level (metre) | F3: Water level on date (metre) | G3: MWL (metre) | H3: Spillway Crest Level (metre) | I3: Blue Alert level (metre) | J3: Orange Alert level (metre) | K3: Red Alert Level (metre) | L3: Live Storage at FRL (MCM) | M3: Live Storage (MCM) | N3: % Storage | O3: % Storage wrt Live Storage at FRL | P3: Inflow (MCM) | Q3: Average Inflow (Cumecs) | R3: Power House Discharge (MCM) | S3: Spill (MCM) | T3: Current Spillway release (Cumecs) | U3: Total Outflow (MCM) | V3: Rain fall (mm) | W3: Remarks | X3: Generation (MU) | AA3: =0.224/8 -> 0.028
A4: 1 | B4: 2 | C4: 3 | D4: 4 | E4: 5 | F4: 6 | I4: 7 | J4: 8 | K4: 9 | M4: 10 | N4: 11 | O4: 15 | P4: 12 | Q4: 13 | R4: 14 | S4: 15 | T4: 16 | U4: 17=14+15 | V4: 18 | W4: 19
A5: 1 | B5: IDUKKI | C5: IDK | D5: 2403 | E5: 2375.33 | F5: 2321.5 | G5: 2408.5 ft | H5: 2373 ft | I5: =E5-8 -> 2367.33 | J5: =E5-2 -> 2373.33 | K5: =E5-1 -> 2374.33 | L5: 1459.49 | M5: 348.877 | N5: =ROUND((M5/L5)*100,2) -> 23.9 | O5: =(#REF!/L5) -> #REF! | P5: 5.036 | Q5: =ROUND((P5*1000000/(24*3600)),2) -> 58.29 | R5: 2.1059 | S5: 0 | T5: 0 | U5: =R5+S5 -> 2.1059 | V5: 47.2 | X5: 3.051
A6: 2 | B6: IDAMALAYAR | C6: EKM | D6: 169 | E6: 161.5 | F6: 139.03 | G6: 171 | H6: 161 | I6: =E6-1.5 -> 160 | J6: =E6-1 -> 160.5 | K6: =E6-0.5 -> 161 | L6: 1017.8 | M6: 290.57 | N6: =ROUND((M6/L6)*100,2) -> 28.55 | O6: =(#REF!/L6) -> #REF! | P6: 4.8275 | Q6: =ROUND((P6*1000000/(24*3600)),2) -> 55.87 | R6: 0 | S6: 0 | T6: 0 | U6: =R6+S6 -> 0 | V6: 30.08 | X6: 0
A7: 3 | B7: KAKKI - ANATHODE | C7: PTTA | D7: 981.46 | E7: 975.36 | F7: 948.21 | G7: 982.16 | H7: 975.36 | I7: =E7-2 -> 973.36 | J7: =E7-1 -> 974.36 | K7: =E7-0.5 -> 974.86 | L7: 446.51 | M7: 101.16 | N7: =ROUND((M7/L7)*100,2) -> 22.66 | O7: =(#REF!/L7) -> #REF! | P7: 1.8135 | Q7: =ROUND((P7*1000000/(24*3600)),2) -> 20.99 | R7: 0.6535 | S7: 0 | T7: 0 | U7: =R7+S7 -> 0.6535 | V7: 59 | X7: 1.054
A8: 4 | B8: BANASURASAGAR (K A S) | C8: WND | D8: 775.6 | E8: 771 | F8: 756.7 | G8: 775.6 | H8: 767 | I8: =E8-1.5 -> 769.5 | J8: =E8-1 -> 770 | K8: =E8-0.5 -> 770.5 | L8: 201 | M8: 24.75 | N8: =ROUND((M8/L8)*100,2) -> 12.31 | O8: =(#REF!/L8) -> #REF! | P8: 1.6 | Q8: =ROUND((P8*1000000/(24*3600)),2) -> 18.52 | S8: 0 | T8: 0 | U8: =R8+S8 -> 0 | V8: 24.8 | W8: Tunnel fully closed on 29.06.2026 at 11.15 am. Tunnel discharge- Nil | Z8: =0.16/8 -> 0.02
A9: 5 | B9: SHOLAYAR | C9: TSR | D9: 2663 | F9: 2592.2 | G9: 2663 ft | H9: 2642 ft | I9: 2658 | J9: 2660 | K9: 2661 | L9: 149.089 | M9: 21.57 | N9: =ROUND((M9/L9)*100,2) -> 14.47 | O9: =(#REF!/L9) -> #REF! | P9: 1.4895 | Q9: =ROUND((P9*1000000/(24*3600)),2) -> 17.24 | R9: 0 | S9: 0 | T9: 0 | U9: =R9+S9 -> 0 | V9: 31.3 | X9: 0
A10: 6 | B10: MADUPETTY | C10: IDK | D10: 1599.59 | F10: 1567.45 | G10: 1599.59 | H10: 1594.71 | I10: 1596 | J10: 1597 | K10: 1598 | L10: 54.77 | M10: 1.74 | N10: =ROUND((M10/L10)*100,2) -> 3.18 | O10: =(#REF!/L10) -> #REF! | P10: 0.139 | Q10: =ROUND((P10*1000000/(24*3600)),2) -> 1.61 | R10: 0 | S10: 0 | T10: =Y10 -> 0 | U10: =R10+S10 -> 0 | V10: 11 | W10: Sluice discharge =0.489MCM | X10: 0 | Y10: =(S10*1000000)/(24*60*60) -> 0
A11: 7 | B11: ANAYIRANKAL | C11: IDK | D11: 1207.02 | F11: 1195.06 | G11: 1210.07 | H11: 1207.02 | I11: 1205.02 | J11: 1206.02 | K11: 1207.02 | L11: 49.83 | M11: 10.139 | N11: =ROUND((M11/L11)*100,2) -> 20.35 | O11: =(#REF!/L11) -> #REF! | P11: 0.1214 | Q11: =ROUND((P11*1000000/(24*3600)),2) -> 1.41 | S11: 0 | T11: 0 | U11: =R11+S11 -> 0 | V11: 10 | W11: (Sluice gate fully closed @ 4.00 pm on 05.06.2026) | X11: 0 | Y11: =ROUND((S11*1000000/(24*3600)),2) -> 0
A12: 8 | B12: PONMUDI | C12: IDK | D12: 707.75 | F12: 691.7 | G12: 708.66 | H12: 701.35 | I12: 704.5 | J12: 705.5 | K12: 706.5 | L12: 47.4 | M12: 16.6569 | N12: =ROUND((M12/L12)*100,2) -> 35.14 | O12: =(#REF!/L12) -> #REF! | P12: 0.5526 | Q12: =ROUND((P12*1000000/(24*3600)),2) -> 6.4 | R12: 0 | S12: 0 | T12: 0 | U12: =R12+S12 -> 0 | V12: 24 | X12: 0 | Y12: =ROUND((S12*1000000/(24*3600)),2) -> 0
A13: 9 | B13: KUTTIYADI (KAKKAYAM) | C13: KKD | D13: 758.04 | F13: 749.41 | G13: 758.04 | H13: 751.64 | I13: 755.5 | J13: 756.5 | K13: 757.5 | L13: 33.98 | M13: 14.6122 | N13: =ROUND((M13/L13)*100,2) -> 43 | O13: =(#REF!/L13) -> #REF! | P13: 1.9609 | Q13: =ROUND((P13*1000000/(24*3600)),2) -> 22.7 | R13: 0 | S13: 0 | T13: 0 | U13: =R13+S13 -> 0 | V13: 82 | X13: 0.089
A14: 10 | B14: PAMBA | C14: PTTA | D14: 986.33 | F14: 964.55 | G14: 986.33 | H14: 981.46 | I14: 982 | J14: 983.5 | K14: 984.5 | L14: 31.15 | M14: 1.05 | N14: =ROUND((M14/L14)*100,2) -> 3.37 | O14: =(#REF!/L14) -> #REF! | P14: 1.339 | Q14: =ROUND((P14*1000000/(24*3600)),2) -> 15.5 | S14: 0 | T14: 0 | U14: =R14+S14 -> 0 | V14: 43 | X14: 0
A15: 11 | B15: PORINGALKUTHU | C15: TSR | D15: 423.98 | F15: 417.4 | G15: 423.98 | H15: 419.41 | I15: 421 | J15: 422 | K15: 423 | L15: 30.3 | M15: 13.9 | N15: =ROUND((M15/L15)*100,2) -> 45.87 | O15: =(#REF!/L15) -> #REF! | P15: 1.4353 | Q15: =ROUND((P15*1000000/(24*3600)),2) -> 16.61 | R15: 1.0353 | S15: 0 | T15: 0 | U15: =R15+S15 -> 1.0353 | V15: 41 | X15: 0.40647 | AB15: =0.0294/8 -> 0.003675
A16: 12 | B16: KUNDALA | C16: IDK | D16: 1758.69 | F16: 1746.6 | G16: 1759.3 | I16: 1755 | J16: 1756 | K16: 1757 | L16: 7.65 | M16: 1.428 | N16: =ROUND((M16/L16)*100,2) -> 18.67 | O16: =(#REF!/L16) -> #REF! | P16: 0.042 | Q16: =ROUND((P16*1000000/(24*3600)),2) -> 0.49 | R16: 0 | S16: 0 | T16: 0 | U16: =R16+S16 -> 0 | V16: 1 | W16: Sluice discharge = 0.00 MCM. All gates are closed | X16: 0 | Y16: =ROUND((S16*1000000/(24*3600)),2) -> 0
A17: 13 | B17: KALLARKUTTY | C17: IDK | D17: 456.59 | F17: 452.35 | G17: 456.9 | H17: 450.2 | K17: 455 | L17: 6.43 | M17: 3.887 | N17: =ROUND((M17/L17)*100,2) -> 60.45 | O17: =(#REF!/L17) -> #REF! | P17: 2.0145 | Q17: =ROUND((P17*1000000/(24*3600)),2) -> 23.32 | R17: 1.9635 | S17: 0 | T17: 0 | U17: =R17+S17 -> 1.9635 | V17: 2 | X17: 0.9223 | Y17: =(S17*1000000)/(24*60*60) -> 0 | Z17: =ROUND((0.054*1000000/(24*3600)),2) -> 0.63
A18: 14 | B18: ERATTAYAR | C18: IDK | D18: 754.38 | F18: 746.6 | G18: 754.38 | H18: 748.28 | K18: 748.28 | L18: 5.292 | M18: 0.5874 | N18: =ROUND((M18/L18)*100,2) -> 11.1 | Q18: =ROUND((P18*1000000/(24*3600)),2) -> 0 | S18: 0 | T18: 0 | U18: =R18+S18 -> 0 | V18: 0 | X18: 0
A19: 15 | B19: LOWER PERIYAR | C19: IDK | D19: 253 | F19: 247.9 | G19: 256 | H19: 237.74 | K19: 252 | L19: 4.55 | M19: 2.479 | N19: =ROUND((M19/L19)*100,2) -> 54.48 | O19: =(#REF!/L19) -> #REF! | P19: 2.8885 | Q19: =ROUND((P19*1000000/(24*3600)),2) -> 33.43 | R19: 3.0365 | S19: 0 | T19: 0 | U19: =R19+S19 -> 3.0365 | V19: 28 | X19: 1.398 | Y19: =ROUND((S19*1000000/(24*3600)),2) -> 0 | AA19: =ROUND((0.1728*1000000/(3*3600)),2) -> 16
A20: 16 | B20: MOOZHIYAR | C20: PTTA | D20: 192.63 | F20: 185.45 | G20: 192.94 | H20: 186.53 | K20: 190 | L20: 1.16 | M20: 0.318 | N20: =ROUND((M20/L20)*100,2) -> 27.41 | O20: =(#REF!/L20) -> #REF! | P20: 0.8883 | Q20: =ROUND((P20*1000000/(24*3600)),2) -> 10.28 | R20: 0.84838 | S20: 0 | T20: 0 | U20: =R20+S20 -> 0.84838 | V20: 26 | X20: 0.26104 | Y20: =ROUND((S20*1000000/(24*3600)),2) -> 0 | Z20: =ROUND((S20*1000000/(24*3600)),2) -> 0
A21: 17 | B21: KALLAR | C21: IDK | D21: 824.48 | F21: 820.2 | G21: 824.48 | H21: 818.38 | K21: 823.5 | L21: 0.763 | M21: 0.1913 | N21: =ROUND((M21/L21)*100,2) -> 25.07 | Q21: =ROUND((P21*1000000/(24*3600)),2) -> 0 | S21: 0 | T21: 0 | U21: =R21+S21 -> 0 | V21: 0 | X21: 0
A22: 18 | B22: SENGULAM | C22: IDK | D22: 847.64 | F22: 846.5 | G22: 849.49 | H22: 847.64 | L22: 0.39 | M22: 0.118 | N22: =ROUND((M22/L22)*100,2) -> 30.26 | O22: =(#REF!/L22) -> #REF! | P22: 0.89 | Q22: =ROUND((P22*1000000/(24*3600)),2) -> 10.3 | R22: 0.913638 | S22: 0 | T22: 0 | U22: =R22+S22 -> 0.913638 | V22: 2.8 | X22: 0.7194
B23: Grand Total | L23: =SUM(L5:L22) -> 3547.554 | M23: =ROUND(SUM(M5:M22),2) -> 854.03 | N23: =ROUND((M23/L23)*100,2) -> 24.07 | O23: =(#REF!/L23) -> #REF!
B25: Spilling Dams : Nil | T25: Deputy Chief Engineer

Sheet 04.07.2026
A1: KERALA STATE ELECTRICITY BOARD LIMITED
A2: DAILY REPORT - WATER LEVELS OF MAJOR RESERVOIRS (As on 04.07.2026) 7.00 AM.
A3: Sl. No. | B3: Name of Reservoir | C3: District | D3: FRL (metre) | E3: Rule level (metre) | F3: Water level on date (metre) | G3: MWL (metre) | H3: Spillway Crest Level (metre) | I3: Blue Alert level (metre) | J3: Orange Alert level (metre) | K3: Red Alert Level (metre) | L3: Live Storage at FRL (MCM) | M3: Live Storage (MCM) | N3: % Storage | O3: % Storage wrt Live Storage at FRL | P3: Inflow (MCM) | Q3: Average Inflow (Cumecs) | R3: Power House Discharge (MCM) | S3: Spill (MCM) | T3: Current Spillway release (Cumecs) | U3: Total Outflow (MCM) | V3: Rain fall (mm) | W3: Remarks | X3: Generation (MU) | AA3: =0.224/8 -> 0.028
A4: 1 | B4: 2 | C4: 3 | D4: 4 | E4: 5 | F4: 6 | I4: 7 | J4: 8 | K4: 9 | M4: 10 | N4: 11 | O4: 15 | P4: 12 | Q4: 13 | R4: 14 | S4: 15 | T4: 16 | U4: 17=14+15 | V4: 18 | W4: 19
A5: 1 | B5: IDUKKI | C5: IDK | D5: 2403 | E5: 2375.33 | F5: 2322.66 | G5: 2408.5 ft | H5: 2373 ft | I5: =E5-8 -> 2367.33 | J5: =E5-2 -> 2373.33 | K5: =E5-1 -> 2374.33 | L5: 1459.49 | M5: 361.28 | N5: =ROUND((M5/L5)*100,2) -> 24.75 | O5: =(#REF!/L5) -> #REF! | P5: 14.335 | Q5: =ROUND((P5*1000000/(24*3600)),2) -> 165.91 | R5: 1.7778 | S5: 0 | T5: 0 | U5: =R5+S5 -> 1.7778 | V5: 79.4 | X5: 2.577
A6: 2 | B6: IDAMALAYAR | C6: EKM | D6: 169 | E6: 161.5 | F6: 139.64 | G6: 171 | H6: 161 | I6: =E6-1.5 -> 160 | J6: =E6-1 -> 160.5 | K6: =E6-0.5 -> 161 | L6: 1017.8 | M6: 302.16 | N6: =ROUND((M6/L6)*100,2) -> 29.69 | O6: =(#REF!/L6) -> #REF! | P6: 11.6129 | Q6: =ROUND((P6*1000000/(24*3600)),2) -> 134.41 | R6: 0 | S6: 0 | T6: 0 | U6: =R6+S6 -> 0 | V6: 46.4 | X6: 0
A7: 3 | B7: KAKKI - ANATHODE | C7: PTTA | D7: 981.46 | E7: 975.36 | F7: 948.95 | G7: 982.16 | H7: 975.36 | I7: =E7-2 -> 973.36 | J7: =E7-1 -> 974.36 | K7: =E7-0.5 -> 974.86 | L7: 446.51 | M7: 105.13 | N7: =ROUND((M7/L7)*100,2) -> 23.54 | O7: =(#REF!/L7) -> #REF! | P7: 4.4536 | Q7: =ROUND((P7*1000000/(24*3600)),2) -> 51.55 | R7: 0.4836 | S7: 0 | T7: 0 | U7: =R7+S7 -> 0.4836 | V7: 117 | X7: 0.78
A8: 4 | B8: BANASURASAGAR (K A S) | C8: WND | D8: 775.6 | E8: 771 | F8: 757.3 | G8: 775.6 | H8: 767 | I8: =E8-1.5 -> 769.5 | J8: =E8-1 -> 770 | K8: =E8-0.5 -> 770.5 | L8: 201 | M8: 28.15 | N8: =ROUND((M8/L8)*100,2) -> 14 | O8: =(#REF!/L8) -> #REF! | P8: 3.4 | Q8: =ROUND((P8*1000000/(24*3600)),2) -> 39.35 | S8: 0 | T8: 0 | U8: =R8+S8 -> 0 | V8: 39.2 | W8: Tunnel fully closed on 29.06.2026 at 11.15 am. Tunnel discharge- Nil | Z8: =0.16/8 -> 0.02
A9: 5 | B9: SHOLAYAR | C9: TSR | D9: 2663 | F9: 2594.2 | G9: 2663 ft | H9: 2642 ft | I9: 2658 | J9: 2660 | K9: 2661 | L9: 149.089 | M9: 23.54 | N9: =ROUND((M9/L9)*100,2) -> 15.79 | O9: =(#REF!/L9) -> #REF! | P9: 1.9652 | Q9: =ROUND((P9*1000000/(24*3600)),2) -> 22.75 | R9: 0 | S9: 0 | T9: 0 | U9: =R9+S9 -> 0 | V9: 46.3 | X9: 0
A10: 6 | B10: MADUPETTY | C10: IDK | D10: 1599.59 | F10: 1567.75 | G10: 1599.59 | H10: 1594.71 | I10: 1596 | J10: 1597 | K10: 1598 | L10: 54.77 | M10: 2.04 | N10: =ROUND((M10/L10)*100,2) -> 3.72 | O10: =(#REF!/L10) -> #REF! | P10: 0.3204 | Q10: =ROUND((P10*1000000/(24*3600)),2) -> 3.71 | R10: 0 | S10: 0 | T10: =Y10 -> 0 | U10: =R10+S10 -> 0 | V10: 24.8 | W10: Sluice discharge =0.0204MCM | X10: 0 | Y10: =(S10*1000000)/(24*60*60) -> 0
A11: 7 | B11: ANAYIRANKAL | C11: IDK | D11: 1207.02 | F11: 1195.14 | G11: 1210.07 | H11: 1207.02 | I11: 1205.02 | J11: 1206.02 | K11: 1207.02 | L11: 49.83 | M11: 10.2777 | N11: =ROUND((M11/L11)*100,2) -> 20.63 | O11: =(#REF!/L11) -> #REF! | P11: 0.1387 | Q11: =ROUND((P11*1000000/(24*3600)),2) -> 1.61 | S11: 0 | T11: 0 | U11: =R11+S11 -> 0 | V11: 22 | W11: (Sluice gate fully closed @ 4.00 pm on 05.06.2026) | X11: 0 | Y11: =ROUND((S11*1000000/(24*3600)),2) -> 0
A12: 8 | B12: PONMUDI | C12: IDK | D12: 707.75 | F12: 692.15 | G12: 708.66 | H12: 701.35 | I12: 704.5 | J12: 705.5 | K12: 706.5 | L12: 47.4 | M12: 17.3674 | N12: =ROUND((M12/L12)*100,2) -> 36.64 | O12: =(#REF!/L12) -> #REF! | P12: 0.7105 | Q12: =ROUND((P12*1000000/(24*3600)),2) -> 8.22 | R12: 0 | S12: 0 | T12: 0 | U12: =R12+S12 -> 0 | V12: 36 | X12: 0 | Y12: =ROUND((S12*1000000/(24*3600)),2) -> 0
A13: 9 | B13: KUTTIYADI (KAKKAYAM) | C13: KKD | D13: 758.04 | F13: 750.72 | G13: 758.04 | H13: 751.64 | I13: 755.5 | J13: 756.5 | K13: 757.5 | L13: 33.98 | M13: 17.233 | N13: =ROUND((M13/L13)*100,2) -> 50.72 | O13: =(#REF!/L13) -> #REF! | P13: 2.9415 | Q13: =ROUND((P13*1000000/(24*3600)),2) -> 34.05 | R13: 0.3207 | S13: 0 | T13: 0 | U13: =R13+S13 -> 0.3207 | V13: 143 | X13: 0.4533
A14: 10 | B14: PAMBA | C14: PTTA | D14: 986.33 | F14: 965.85 | G14: 986.33 | H14: 981.46 | I14: 982 | J14: 983.5 | K14: 984.5 | L14: 31.15 | M14: 2.09 | N14: =ROUND((M14/L14)*100,2) -> 6.71 | O14: =(#REF!/L14) -> #REF! | P14: 3.538 | Q14: =ROUND((P14*1000000/(24*3600)),2) -> 40.95 | S14: 0 | T14: 0 | U14: =R14+S14 -> 0 | V14: 88 | X14: 0
A15: 11 | B15: PORINGALKUTHU | C15: TSR | D15: 423.98 | F15: 419.1 | G15: 423.98 | H15: 419.41 | I15: 421 | J15: 422 | K15: 423 | L15: 30.3 | M15: 17.5 | N15: =ROUND((M15/L15)*100,2) -> 57.76 | O15: =(#REF!/L15) -> #REF! | P15: 5.7652 | Q15: =ROUND((P15*1000000/(24*3600)),2) -> 66.73 | R15: 2.1652 | S15: 0 | T15: 0 | U15: =R15+S15 -> 2.1652 | V15: 57.3 | X15: 0.8684 | AB15: =0.0294/8 -> 0.003675
A16: 12 | B16: KUNDALA | C16: IDK | D16: 1758.69 | F16: 1746.7 | G16: 1759.3 | I16: 1755 | J16: 1756 | K16: 1757 | L16: 7.65 | M16: 1.456 | N16: =ROUND((M16/L16)*100,2) -> 19.03 | O16: =(#REF!/L16) -> #REF! | P16: 0.028 | Q16: =ROUND((P16*1000000/(24*3600)),2) -> 0.32 | R16: 0 | S16: 0 | T16: 0 | U16: =R16+S16 -> 0 | V16: 3.4 | W16: Sluice discharge = 0.00 MCM. All gates are closed | X16: 0 | Y16: =ROUND((S16*1000000/(24*3600)),2) -> 0
A17: 13 | B17: KALLARKUTTY | C17: IDK | D17: 456.59 | F17: 453.6 | G17: 456.9 | H17: 450.2 | K17: 455 | L17: 6.43 | M17: 4.57 | N17: =ROUND((M17/L17)*100,2) -> 71.07 | O17: =(#REF!/L17) -> #REF! | P17: 2.8662 | Q17: =ROUND((P17*1000000/(24*3600)),2) -> 33.17 | R17: 2.1834 | S17: 0 | T17: 0 | U17: =R17+S17 -> 2.1834 | V17: 36 | X17: 1.0199 | Y17: =(S17*1000000)/(24*60*60) -> 0 | Z17: =ROUND((0.054*1000000/(24*3600)),2) -> 0.63
A18: 14 | B18: ERATTAYAR | C18: IDK | D18: 754.38 | F18: 746.87 | G18: 754.38 | H18: 748.28 | K18: 748.28 | L18: 5.292 | M18: 0.6354 | N18: =ROUND((M18/L18)*100,2) -> 12.01 | Q18: =ROUND((P18*1000000/(24*3600)),2) -> 0 | S18: 0 | T18: 0 | U18: =R18+S18 -> 0 | V18: 0 | X18: 0
A19: 15 | B19: LOWER PERIYAR | C19: IDK | D19: 253 | F19: 252.2 | G19: 256 | H19: 237.74 | K19: 252 | L19: 4.55 | M19: 4.206 | N19: =ROUND((M19/L19)*100,2) -> 92.44 | O19: =(#REF!/L19) -> #REF! | P19: 5.6518 | Q19: =ROUND((P19*1000000/(24*3600)),2) -> 65.41 | R19: 3.9248 | S19: 0 | T19: 0 | U19: =R19+S19 -> 3.9248 | V19: 50 | X19: 1.807 | Y19: =ROUND((S19*1000000/(24*3600)),2) -> 0 | AA19: =ROUND((0.1728*1000000/(3*3600)),2) -> 16
A20: 16 | B20: MOOZHIYAR | C20: PTTA | D20: 192.63 | F20: 187.9 | G20: 192.94 | H20: 186.53 | K20: 190 | L20: 1.16 | M20: 0.559 | N20: =ROUND((M20/L20)*100,2) -> 48.19 | O20: =(#REF!/L20) -> #REF! | P20: 1.3554 | Q20: =ROUND((P20*1000000/(24*3600)),2) -> 15.69 | R20: 1.12502 | S20: 0 | T20: 0 | U20: =R20+S20 -> 1.12502 | V20: 44 | X20: 0.3461 | Y20: =ROUND((S20*1000000/(24*3600)),2) -> 0 | Z20: =ROUND((S20*1000000/(24*3600)),2) -> 0
A21: 17 | B21: KALLAR | C21: IDK | D21: 824.48 | F21: 820.3 | G21: 824.48 | H21: 818.38 | K21: 823.5 | L21: 0.763 | M21: 0.1949 | N21: =ROUND((M21/L21)*100,2) -> 25.54 | Q21: =ROUND((P21*1000000/(24*3600)),2) -> 0 | S21: 0 | T21: 0 | U21: =R21+S21 -> 0 | V21: 0 | X21: 0
A22: 18 | B22: SENGULAM | C22: IDK | D22: 847.64 | F22: 846.85 | G22: 849.49 | H22: 847.64 | L22: 0.39 | M22: 0.201 | N22: =ROUND((M22/L22)*100,2) -> 51.54 | O22: =(#REF!/L22) -> #REF! | P22: 1.2313 | Q22: =ROUND((P22*1000000/(24*3600)),2) -> 14.25 | R22: 1.148588 | S22: 0 | T22: 0 | U22: =R22+S22 -> 1.148588 | V22: 12.6 | X22: 0.9044
B23: Grand Total | L23: =SUM(L5:L22) -> 3547.554 | M23: =ROUND(SUM(M5:M22),2) -> 898.59 | N23: =ROUND((M23/L23)*100,2) -> 25.33 | O23: =(#REF!/L23) -> #REF!
B25: Spilling Dams : Nil | T25: Deputy Chief Engineer

Sheet 05.07.2026
A1: KERALA STATE ELECTRICITY BOARD LIMITED
A2: DAILY REPORT - WATER LEVELS OF MAJOR RESERVOIRS (As on 05.07.2026) 7.00 AM.
A3: Sl. No. | B3: Name of Reservoir | C3: District | D3: FRL (metre) | E3: Rule level (metre) | F3: Water level on date (metre) | G3: MWL (metre) | H3: Spillway Crest Level (metre) | I3: Blue Alert level (metre) | J3: Orange Alert level (metre) | K3: Red Alert Level (metre) | L3: Live Storage at FRL (MCM) | M3: Live Storage (MCM) | N3: % Storage | O3: % Storage wrt Live Storage at FRL | P3: Inflow (MCM) | Q3: Average Inflow (Cumecs) | R3: Power House Discharge (MCM) | S3: Spill (MCM) | T3: Current Spillway release (Cumecs) | U3: Total Outflow (MCM) | V3: Rain fall (mm) | W3: Remarks | X3: Generation (MU) | AA3: =0.224/8 -> 0.028
A4: 1 | B4: 2 | C4: 3 | D4: 4 | E4: 5 | F4: 6 | I4: 7 | J4: 8 | K4: 9 | M4: 10 | N4: 11 | O4: 15 | P4: 12 | Q4: 13 | R4: 14 | S4: 15 | T4: 16 | U4: 17=14+15 | V4: 18 | W4: 19
A5: 1 | B5: IDUKKI | C5: IDK | D5: 2403 | E5: 2375.33 | F5: 2323.82 | G5: 2408.5 ft | H5: 2373 ft | I5: =E5-8 -> 2367.33 | J5: =E5-2 -> 2373.33 | K5: =E5-1 -> 2374.33 | L5: 1459.49 | M5: 373.673 | N5: =ROUND((M5/L5)*100,2) -> 25.6 | O5: =(#REF!/L5) -> #REF! | P5: 14.542 | Q5: =ROUND((P5*1000000/(24*3600)),2) -> 168.31 | R5: 1994 | S5: 0 | T5: 0 | U5: =R5+S5 -> 1994 | V5: 18.2 | X5: 2.892
A6: 2 | B6: IDAMALAYAR | C6: EKM | D6: 169 | E6: 161.5 | F6: 140.15 | G6: 171 | H6: 161 | I6: =E6-1.5 -> 160 | J6: =E6-1 -> 160.5 | K6: =E6-0.5 -> 161 | L6: 1017.8 | M6: 311.933 | N6: =ROUND((M6/L6)*100,2) -> 30.65 | O6: =(#REF!/L6) -> #REF! | P6: 9.9964 | Q6: =ROUND((P6*1000000/(24*3600)),2) -> 115.7 | R6: 0.2209 | S6: 0 | T6: 0 | U6: =R6+S6 -> 0.2209 | V6: 12 | X6: 0.0532
A7: 3 | B7: KAKKI - ANATHODE | C7: PTTA | D7: 981.46 | E7: 975.36 | F7: 949.96 | G7: 982.16 | H7: 975.36 | I7: =E7-2 -> 973.36 | J7: =E7-1 -> 974.36 | K7: =E7-0.5 -> 974.86 | L7: 446.51 | M7: 110.78 | N7: =ROUND((M7/L7)*100,2) -> 24.81 | O7: =(#REF!/L7) -> #REF! | P7: 6.1109 | Q7: =ROUND((P7*1000000/(24*3600)),2) -> 70.73 | R7: 0.4609 | S7: 0 | T7: 0 | U7: =R7+S7 -> 0.4609 | V7: 44 | X7: 0.7434
A8: 4 | B8: BANASURASAGAR (K A S) | C8: WND | D8: 775.6 | E8: 771 | F8: 757.8 | G8: 775.6 | H8: 767 | I8: =E8-1.5 -> 769.5 | J8: =E8-1 -> 770 | K8: =E8-0.5 -> 770.5 | L8: 201 | M8: 30.75 | N8: =ROUND((M8/L8)*100,2) -> 15.3 | O8: =(#REF!/L8) -> #REF! | P8: 2.6 | Q8: =ROUND((P8*1000000/(24*3600)),2) -> 30.09 | S8: 0 | T8: 0 | U8: =R8+S8 -> 0 | V8: 55.6 | W8: Tunnel fully closed on 29.06.2026 at 11.15 am. Tunnel discharge- Nil | Z8: =0.16/8 -> 0.02
A9: 5 | B9: SHOLAYAR | C9: TSR | D9: 2663 | F9: 2595.2 | G9: 2663 ft | H9: 2642 ft | I9: 2658 | J9: 2660 | K9: 2661 | L9: 149.089 | M9: 24.56 | N9: =ROUND((M9/L9)*100,2) -> 16.47 | O9: =(#REF!/L9) -> #REF! | P9: 1.0251 | Q9: =ROUND((P9*1000000/(24*3600)),2) -> 11.86 | R9: 0 | S9: 0 | T9: 0 | U9: =R9+S9 -> 0 | V9: 19.1 | X9: 0
A10: 6 | B10: MADUPETTY | C10: IDK | D10: 1599.59 | F10: 1568.1 | G10: 1599.59 | H10: 1594.71 | I10: 1596 | J10: 1597 | K10: 1598 | L10: 54.77 | M10: 2.39 | N10: =ROUND((M10/L10)*100,2) -> 4.36 | O10: =(#REF!/L10) -> #REF! | P10: 0.35 | Q10: =ROUND((P10*1000000/(24*3600)),2) -> 4.05 | R10: 0 | S10: 0 | T10: =Y10 -> 0 | U10: =R10+S10 -> 0 | V10: 17 | W10: Sluice discharge =0.00 MCM | X10: 0 | Y10: =(S10*1000000)/(24*60*60) -> 0
A11: 7 | B11: ANAYIRANKAL | C11: IDK | D11: 1207.02 | F11: 1195.2 | G11: 1210.07 | H11: 1207.02 | I11: 1205.02 | J11: 1206.02 | K11: 1207.02 | L11: 49.83 | M11: 10.3818 | N11: =ROUND((M11/L11)*100,2) -> 20.83 | O11: =(#REF!/L11) -> #REF! | P11: 0.1041 | Q11: =ROUND((P11*1000000/(24*3600)),2) -> 1.2 | S11: 0 | T11: 0 | U11: =R11+S11 -> 0 | V11: 5 | W11: (Sluice gate fully closed @ 4.00 pm on 05.06.2026) | X11: 0 | Y11: =ROUND((S11*1000000/(24*3600)),2) -> 0
A12: 8 | B12: PONMUDI | C12: IDK | D12: 707.75 | F12: 692.7 | G12: 708.66 | H12: 701.35 | I12: 704.5 | J12: 705.5 | K12: 706.5 | L12: 47.4 | M12: 18.2359 | N12: =ROUND((M12/L12)*100,2) -> 38.47 | O12: =(#REF!/L12) -> #REF! | P12: 0.8685 | Q12: =ROUND((P12*1000000/(24*3600)),2) -> 10.05 | R12: 0 | S12: 0 | T12: 0 | U12: =R12+S12 -> 0 | V12: 14 | X12: 0 | Y12: =ROUND((S12*1000000/(24*3600)),2) -> 0
A13: 9 | B13: KUTTIYADI (KAKKAYAM) | C13: KKD | D13: 758.04 | F13: 750.11 | G13: 758.04 | H13: 751.64 | I13: 755.5 | J13: 756.5 | K13: 757.5 | L13: 33.98 | M13: 16.013 | N13: =ROUND((M13/L13)*100,2) -> 47.12 | O13: =(#REF!/L13) -> #REF! | P13: 1.6274 | Q13: =ROUND((P13*1000000/(24*3600)),2) -> 18.84 | R13: 2.8474 | S13: 0 | T13: 0 | U13: =R13+S13 -> 2.8474 | V13: 31 | X13: 4.0229
A14: 10 | B14: PAMBA | C14: PTTA | D14: 986.33 | F14: 966.75 | G14: 986.33 | H14: 981.46 | I14: 982 | J14: 983.5 | K14: 984.5 | L14: 31.15 | M14: 2.93 | N14: =ROUND((M14/L14)*100,2) -> 9.41 | O14: =(#REF!/L14) -> #REF! | P14: 4.656 | Q14: =ROUND((P14*1000000/(24*3600)),2) -> 53.89 | S14: 0 | T14: 0 | U14: =R14+S14 -> 0 | V14: 36 | X14: 0
A15: 11 | B15: PORINGALKUTHU | C15: TSR | D15: 423.98 | F15: 419.5 | G15: 423.98 | H15: 419.41 | I15: 421 | J15: 422 | K15: 423 | L15: 30.3 | M15: 18.5 | N15: =ROUND((M15/L15)*100,2) -> 61.06 | O15: =(#REF!/L15) -> #REF! | P15: 6.7412 | Q15: =ROUND((P15*1000000/(24*3600)),2) -> 78.02 | R15: 4.7486 | S15: 0 | T15: 0 | U15: =R15+S15 -> 4.7486 | V15: 15 | X15: 1.86564 | AB15: =0.0294/8 -> 0.003675
A16: 12 | B16: KUNDALA | C16: IDK | D16: 1758.69 | F16: 1746.8 | G16: 1759.3 | I16: 1755 | J16: 1756 | K16: 1757 | L16: 7.65 | M16: 1.484 | N16: =ROUND((M16/L16)*100,2) -> 19.4 | O16: =(#REF!/L16) -> #REF! | P16: 0.028 | Q16: =ROUND((P16*1000000/(24*3600)),2) -> 0.32 | R16: 0 | S16: 0 | T16: 0 | U16: =R16+S16 -> 0 | V16: 3 | W16: Sluice discharge = 0.00 MCM. All gates are closed | X16: 0 | Y16: =ROUND((S16*1000000/(24*3600)),2) -> 0
A17: 13 | B17: KALLARKUTTY | C17: IDK | D17: 456.59 | F17: 454.35 | G17: 456.9 | H17: 450.2 | K17: 455 | L17: 6.43 | M17: 5.046 | N17: =ROUND((M17/L17)*100,2) -> 78.48 | O17: =(#REF!/L17) -> #REF! | P17: 3.8011 | Q17: =ROUND((P17*1000000/(24*3600)),2) -> 43.99 | R17: 1.5595 | S17: 0 | T17: 0 | U17: =R17+S17 -> 1.5595 | V17: 23 | X17: 3.325333 | Y17: =(S17*1000000)/(24*60*60) -> 0 | Z17: =ROUND((0.054*1000000/(24*3600)),2) -> 0.63
A18: 14 | B18: ERATTAYAR | C18: IDK | D18: 754.38 | F18: 746.8 | G18: 754.38 | H18: 748.28 | K18: 748.28 | L18: 5.292 | M18: 0.6741 | N18: =ROUND((M18/L18)*100,2) -> 12.74 | Q18: =ROUND((P18*1000000/(24*3600)),2) -> 0 | S18: 0 | T18: 0 | U18: =R18+S18 -> 0 | V18: 0 | X18: 0
A19: 15 | B19: LOWER PERIYAR | C19: IDK | D19: 253 | F19: 251.9 | G19: 256 | H19: 237.74 | K19: 252 | L19: 4.55 | M19: 4.078 | N19: =ROUND((M19/L19)*100,2) -> 89.63 | O19: =(#REF!/L19) -> #REF! | P19: 6.0361 | Q19: =ROUND((P19*1000000/(24*3600)),2) -> 69.86 | R19: 6.1641 | S19: 0 | T19: 0 | U19: =R19+S19 -> 6.1641 | V19: 22 | X19: 2.838 | Y19: =ROUND((S19*1000000/(24*3600)),2) -> 0 | AA19: =ROUND((0.1728*1000000/(3*3600)),2) -> 16
A20: 16 | B20: MOOZHIYAR | C20: PTTA | D20: 192.63 | F20: 185.6 | G20: 192.94 | H20: 186.53 | K20: 190 | L20: 1.16 | M20: 0.327 | N20: =ROUND((M20/L20)*100,2) -> 28.19 | O20: =(#REF!/L20) -> #REF! | P20: 1.4224 | Q20: =ROUND((P20*1000000/(24*3600)),2) -> 16.46 | R20: 1.4245 | S20: 0 | T20: 0 | U20: =R20+S20 -> 1.4245 | V20: 25 | X20: 0.43831 | Y20: =ROUND((S20*1000000/(24*3600)),2) -> 0 | Z20: =ROUND((S20*1000000/(24*3600)),2) -> 0
A21: 17 | B21: KALLAR | C21: IDK | D21: 824.48 | F21: 820.3 | G21: 824.48 | H21: 818.38 | K21: 823.5 | L21: 0.763 | M21: 0.1949 | N21: =ROUND((M21/L21)*100,2) -> 25.54 | Q21: =ROUND((P21*1000000/(24*3600)),2) -> 0 | S21: 0 | T21: 0 | U21: =R21+S21 -> 0 | V21: 0 | X21: 0
A22: 18 | B22: SENGULAM | C22: IDK | D22: 847.64 | F22: 846.8 | G22: 849.49 | H22: 847.64 | L22: 0.39 | M22: 0.189 | N22: =ROUND((M22/L22)*100,2) -> 48.46 | O22: =(#REF!/L22) -> #REF! | P22: 1.1367 | Q22: =ROUND((P22*1000000/(24*3600)),2) -> 13.16 | R22: 1.148567 | S22: 0 | T22: 0 | U22: =R22+S22 -> 1.148567 | V22: 3.9 | X22: 0.62
B23: Grand Total | L23: =SUM(L5:L22) -> 3547.554 | M23: =ROUND(SUM(M5:M22),2) -> 932.14 | N23: =ROUND((M23/L23)*100,2) -> 26.28 | O23: =(#REF!/L23) -> #REF!
B25: Spilling Dams : Nil | T25: Deputy Chief Engineer

Sheet 06.07.2026
A1: KERALA STATE ELECTRICITY BOARD LIMITED
A2: DAILY REPORT - WATER LEVELS OF MAJOR RESERVOIRS (As on 06.07.2026) 7.00 AM.
A3: Sl. No. | B3: Name of Reservoir | C3: District | D3: FRL (metre) | E3: Rule level (metre) | F3: Water level on date (metre) | G3: MWL (metre) | H3: Spillway Crest Level (metre) | I3: Blue Alert level (metre) | J3: Orange Alert level (metre) | K3: Red Alert Level (metre) | L3: Live Storage at FRL (MCM) | M3: Live Storage (MCM) | N3: % Storage | O3: % Storage wrt Live Storage at FRL | P3: Inflow (MCM) | Q3: Average Inflow (Cumecs) | R3: Power House Discharge (MCM) | S3: Spill (MCM) | T3: Current Spillway release (Cumecs) | U3: Total Outflow (MCM) | V3: Rain fall (mm) | W3: Remarks | X3: Generation (MU) | AA3: =0.224/8 -> 0.028
A4: 1 | B4: 2 | C4: 3 | D4: 4 | E4: 5 | F4: 6 | I4: 7 | J4: 8 | K4: 9 | M4: 10 | N4: 11 | O4: 15 | P4: 12 | Q4: 13 | R4: 14 | S4: 15 | T4: 16 | U4: 17=14+15 | V4: 18 | W4: 19
A5: 1 | B5: IDUKKI | C5: IDK | D5: 2403 | E5: 2375.33 | F5: 2324.56 | G5: 2408.5 ft | H5: 2373 ft | I5: =E5-8 -> 2367.33 | J5: =E5-2 -> 2373.33 | K5: =E5-1 -> 2374.33 | L5: 1459.49 | M5: 381.573 | N5: =ROUND((M5/L5)*100,2) -> 26.14 | O5: =(#REF!/L5) -> #REF! | P5: 8.588 | Q5: =ROUND((P5*1000000/(24*3600)),2) -> 99.4 | R5: 0.5335 | S5: 0 | T5: 0 | U5: =R5+S5 -> 0.5335 | V5: 0.8 | X5: 0.774
A6: 2 | B6: IDAMALAYAR | C6: EKM | D6: 169 | E6: 161.5 | F6: 140.44 | G6: 171 | H6: 161 | I6: =E6-1.5 -> 160 | J6: =E6-1 -> 160.5 | K6: =E6-0.5 -> 161 | L6: 1017.8 | M6: 317.602 | N6: =ROUND((M6/L6)*100,2) -> 31.2 | O6: =(#REF!/L6) -> #REF! | P6: 5.6828 | Q6: =ROUND((P6*1000000/(24*3600)),2) -> 65.77 | R6: 0 | S6: 0 | T6: 0 | U6: =R6+S6 -> 0 | V6: 2 | X6: 0
A7: 3 | B7: KAKKI - ANATHODE | C7: PTTA | D7: 981.46 | E7: 975.36 | F7: 950.78 | G7: 982.16 | H7: 975.36 | I7: =E7-2 -> 973.36 | J7: =E7-1 -> 974.36 | K7: =E7-0.5 -> 974.86 | L7: 446.51 | M7: 115.5 | N7: =ROUND((M7/L7)*100,2) -> 25.87 | O7: =(#REF!/L7) -> #REF! | P7: 4.734 | Q7: =ROUND((P7*1000000/(24*3600)),2) -> 54.79 | R7: 0.014 | S7: 0 | T7: 0 | U7: =R7+S7 -> 0.014 | V7: 0 | X7: 0.0225
A8: 4 | B8: BANASURASAGAR (K A S) | C8: WND | D8: 775.6 | E8: 771 | F8: 758 | G8: 775.6 | H8: 767 | I8: =E8-1.5 -> 769.5 | J8: =E8-1 -> 770 | K8: =E8-0.5 -> 770.5 | L8: 201 | M8: 31.85 | N8: =ROUND((M8/L8)*100,2) -> 15.85 | O8: =(#REF!/L8) -> #REF! | P8: 1.1 | Q8: =ROUND((P8*1000000/(24*3600)),2) -> 12.73 | S8: 0 | T8: 0 | U8: =R8+S8 -> 0 | V8: 13.6 | W8: Tunnel fully closed on 29.06.2026 at 11.15 am. Tunnel discharge- Nil | Z8: =0.16/8 -> 0.02
A9: 5 | B9: SHOLAYAR | C9: TSR | D9: 2663 | F9: 2596.3 | G9: 2663 ft | H9: 2642 ft | I9: 2658 | J9: 2660 | K9: 2661 | L9: 149.089 | M9: 25.72 | N9: =ROUND((M9/L9)*100,2) -> 17.25 | O9: =(#REF!/L9) -> #REF! | P9: 1.161 | Q9: =ROUND((P9*1000000/(24*3600)),2) -> 13.44 | R9: 0 | S9: 0 | T9: 0 | U9: =R9+S9 -> 0 | V9: 10.4 | X9: 0
A10: 6 | B10: MADUPETTY | C10: IDK | D10: 1599.59 | F10: 1568.4 | G10: 1599.59 | H10: 1594.71 | I10: 1596 | J10: 1597 | K10: 1598 | L10: 54.77 | M10: 2.69 | N10: =ROUND((M10/L10)*100,2) -> 4.91 | O10: =(#REF!/L10) -> #REF! | P10: 0.3 | Q10: =ROUND((P10*1000000/(24*3600)),2) -> 3.47 | R10: 0 | S10: 0 | T10: =Y10 -> 0 | U10: =R10+S10 -> 0 | V10: 1 | W10: Sluice discharge =0.00 MCM | X10: 0 | Y10: =(S10*1000000)/(24*60*60) -> 0
A11: 7 | B11: ANAYIRANKAL | C11: IDK | D11: 1207.02 | F11: 1195.26 | G11: 1210.07 | H11: 1207.02 | I11: 1205.02 | J11: 1206.02 | K11: 1207.02 | L11: 49.83 | M11: 10.4858 | N11: =ROUND((M11/L11)*100,2) -> 21.04 | O11: =(#REF!/L11) -> #REF! | P11: 0.104 | Q11: =ROUND((P11*1000000/(24*3600)),2) -> 1.2 | S11: 0 | T11: 0 | U11: =R11+S11 -> 0 | V11: 0 | W11: (Sluice gate fully closed @ 4.00 pm on 05.06.2026) | X11: 0 | Y11: =ROUND((S11*1000000/(24*3600)),2) -> 0
